Workbook

Sheet Информация о Чемпионате
A3: Компетенция | B3: Программные решения для бизнеса
A4: Наименование этапа Чемпионата | B4: Региональный этап чемпионат по профессиональному мастерству "Профессионалы" в 2026 г.
A5: Субъект РФ (регион проведения) | B5: Санкт-Петербург
A6: Базовая организация расположения конкурсной площадки | B6: Санкт-Петербургский колледж телекоммуникаций им. Э.Т. Кренкеля ФГБОУ ВО "Санкт-Петербургский государственный университет телекоммуникаций им. проф. М.А.Бонч-Бруевича"
A7: Адрес конкурсной площадки | B7: г. Санкт-Петербург, наб. реки Мойки, д. 61, лит. А.
A8: Даты проведения | B8: 02 февраля 2026 года - 06 января 2026 года
A9: Главный эксперт | B9: Кривоносова Наталья Викторовна
A10: Электронная почта ГЭ | B10: nvkrivonosowa@mail.ru
A11: Моб.телефон ГЭ | B11: +7(952)385-42-25
A12: Технический администратор площадки | B12: Андреев Михаил Дмитриевич
A13: Электронная почта ТАП | B13: andreev.mikhail.8b@gmail.com
A14: Моб.телефон ТАП | B14: +79201595535
A15: Количество конкурсантов | B15: 10
A16: Количество рабочих мест | B16: 10
A17: Количество экспертов (ГЭ+ЭН+ИЭ)+ТАП | B17: 13
A20: ЭН - эксперт-наставник
A21: ГЭ - главный эксперт
A22: ИЭ - индустриальный эксперт
A23: ТАП - технический администратор площадки

Sheet Общая инфраструктура
A1: Инфраструктурный лист для оснащения конкурсной площадки
A2: ='Информация о Чемпионате'!B4 -> Региональный этап чемпионат по профессиональному мастерству "Профессионалы" в 2026 г.
A3: по компетенции
A4: ='Информация о Чемпионате'!B3 -> Программные решения для бизнеса
A5: Основная информация о конкурсной площадке:
A6: Субъект Российской Федерации: | C6: ='Информация о Чемпионате'!B5 -> Санкт-Петербург
A7: Базовая организация расположения конкурсной площадки: | D7: ='Информация о Чемпионате'!B6 -> Санкт-Петербургский колледж телекоммуникаций им. Э.Т. Кренкеля ФГБОУ ВО "Санкт-Петербургский государственный университет телекоммуникаций им. проф. М.А.Бонч-Бруевича"
A8: Адрес базовой организации: | C8: ='Информация о Чемпионате'!B7 -> г. Санкт-Петербург, наб. реки Мойки, д. 61, лит. А.
A9: Главный эксперт: | C9: ='Информация о Чемпионате'!B9 -> Кривоносова Наталья Викторовна | E9: ='Информация о Чемпионате'!B10 -> nvkrivonosowa@mail.ru | G9: ='Информация о Чемпионате'!B11 -> +7(952)385-42-25
A10: Технический администратор площадки: | C10: ='Информация о Чемпионате'!B12 -> Андреев Михаил Дмитриевич | E10: ='Информация о Чемпионате'!B13 -> andreev.mikhail.8b@gmail.com | G10: ='Информация о Чемпионате'!B14 -> +79201595535
A11: Количество экспертов (ЭН+ГЭ+ИЭ) + ТАП: | C11: ='Информация о Чемпионате'!B17 -> 13
A12: Количество конкурсантов: | C12: ='Информация о Чемпионате'!B15 -> 10
A13: Количество рабочих мест: | C13: ='Информация о Чемпионате'!B16 -> 10
A14: Даты проведения: | C14: ='Информация о Чемпионате'!B8 -> 02 февраля 2026 года - 06 января 2026 года
A15: Общая зона конкурсной площадки (оборудование, инструмент, мебель)
A16: Требования к обеспечению зоны (коммуникации, площадь, сети, количество рабочих мест и др.):
A17: Площадь зоны: 146 кв.м.
A18: Освещение: верхнее искусственное освещение 300 люкс
A19: Интернет : Подключение к проводному интернету
A20: Электричество: 5 подключений к сети (220 Вольт)
A21: Контур заземления для электропитания и сети слаботочных подключений: не требуется
A22: Покрытие пола: линолеум - на всю зону
A23: Подведение/ отведение ГХВС: не требуется
A24: Подведение сжатого воздуха: не требуется
A25: Интернет : Проводной Интернет - 1 точка. Общая пропускная способность 1Гбит/сек
A26: Электричество: 13 точек 220Вольт, суммарная мощность исходя из пиковой нагрузки используемого оборудования
A27: Контур заземления для электропитания и сети слаботочных подключений (при необходимости): требуется
A28: № | B28: Наименование | C28: Краткие (рамочные) технические характеристики | D28: Вид | E28: Количество | F28: Единица измерения | G28: Итоговое количество | H28: Рекомендации представителей индустрии (указывается конкретное оборудование)
A29: 1 | B29: Коммутатор | C29: Eltex MES2324B | D29: Оборудование IT | E29: 1 | F29: шт | G29: 1
A30: 2 | B30: Wi-Fi маршрутизатор | C30: Xiaomi Mi 4 | D30: Оборудование IT | E30: 1 | F30: шт | G30: 1
A31: 3 | B31: Офисный стол | C31: Офисный стол 70*140 | D31: Мебель | E31: 17 | F31: шт | G31: 17
A32: 4 | B32: Офисный стул | C32: Офисный стул | D32: Мебель | E32: 28 | F32: шт | G32: 28
A33: 5 | B33: Стол компьютерый | C33: Стол компьютерный 61*101 | D33: Мебель | E33: 10 | F33: шт | G33: =E33 -> 10
A34: 6 | B34: Кресло компьютерное | C34: Кресло компьютерное | D34: Мебель | E34: 10 | F34: шт | G34: =E34 -> 10
A35: 7 | B35: Кулер | C35: Кулер 19 л (холодная вода) | D35: Оборудование | E35: 1 | F35: шт | G35: 1
A36: 8 | B36: Короб для системного блока | C36: Короб для системного блока 200*500 | D36: Мебель | E36: 2 | F36: шт | G36: 2
A37: 9 | B37: Флипчарт | C37: Флипчарт 70*100 | D37: Мебель | E37: 1 | F37: шт | G37: 1
A38: 10 | B38: Комод | C38: Комод 45*90 | D38: Мебель | E38: 1 | F38: шт | G38: 1
A39: 11 | B39: Проектор | C39: Проектор Epson EB-X31 | D39: Оборудование IT | E39: 1 | F39: шт | G39: 1
A40: 12 | B40: Проектор мультимедйный | C40: Проектор BenQ MX808STH | D40: Оборудование IT | E40: 1 | F40: шт | G40: 1
...

Sheet Рабочее место конкурсантов
A1: Инфраструктурный лист для оснащения конкурсной площадки
A2: ='Информация о Чемпионате'!B4 -> Региональный этап чемпионат по профессиональному мастерству "Профессионалы" в 2026 г.
A3: по компетенции
A4: ='Информация о Чемпионате'!B3 -> Программные решения для бизнеса
A5: Основная информация о конкурсной площадке:
A6: Субъект Российской Федерации: | C6: ='Информация о Чемпионате'!B5 -> Санкт-Петербург
A7: Базовая организация расположения конкурсной площадки: | D7: ='Информация о Чемпионате'!B6 -> Санкт-Петербургский колледж телекоммуникаций им. Э.Т. Кренкеля ФГБОУ ВО "Санкт-Петербургский государственный университет телекоммуникаций им. проф. М.А.Бонч-Бруевича"
A8: Адрес базовой организации: | C8: ='Информация о Чемпионате'!B7 -> г. Санкт-Петербург, наб. реки Мойки, д. 61, лит. А.
A9: Главный эксперт: | C9: ='Информация о Чемпионате'!B9 -> Кривоносова Наталья Викторовна | E9: ='Информация о Чемпионате'!B10 -> nvkrivonosowa@mail.ru | G9: ='Информация о Чемпионате'!B11 -> +7(952)385-42-25
A10: Технический администратор площадки: | C10: ='Информация о Чемпионате'!B12 -> Андреев Михаил Дмитриевич | E10: ='Информация о Чемпионате'!B13 -> andreev.mikhail.8b@gmail.com | G10: ='Информация о Чемпионате'!B14 -> +79201595535
A11: Количество экспертов (ЭН+ГЭ+ИЭ) + ТАП: | C11: ='Информация о Чемпионате'!B17 -> 13
A12: Количество конкурсантов: | C12: ='Информация о Чемпионате'!B15 -> 10
A13: Количество рабочих мест: | C13: ='Информация о Чемпионате'!B16 -> 10
A14: Даты проведения: | C14: ='Информация о Чемпионате'!B8 -> 02 февраля 2026 года - 06 января 2026 года
A15: Рабочее место Конкурсанта (основное оборудование, вспомогательное оборудование, инструмент (по количеству рабочих мест))
A16: Требования к обеспечению зоны (коммуникации, площадь, сети, количество рабочих мест и др.):
A17: Площадь зоны: 96 кв.м.
A18: Освещение: верхнее искусственное освещение 300 люкс
A19: Интернет : Подключение к проводному интернету
A20: Электричество: 3 подключения к сети по (220 Вольт)
A21: Контур заземления для электропитания и сети слаботочных подключений: не требуется
A22: Покрытие пола: линолеум - 96 м2 на всю зону
A23: Подведение/ отведение ГХВС: не требуется
A24: Подведение сжатого воздуха: не требуется
A25: № | B25: Наименование | C25: Краткие (рамочные) технические характеристики | D25: Вид | E25: Количество | F25: Единица измерения | G25: Итоговое количество | H25: Рекомендации представителей индустрии (указывается конкретное оборудование)
A26: 1 | B26: Стол компьютерый | C26: Стол компьютерный 61*101 | D26: Мебель | E26: 1 | F26: шт. ( на 1 раб.место) | G26: =E26*$C$13 -> 10
A27: 2 | B27: Кресло компьютерное | C27: Кресло компьютерное | D27: Мебель | E27: 1 | F27: шт. ( на 1 раб.место) | G27: =E27*$C$13 -> 10
A28: 3 | B28: Короб для системного блока | C28: Короб для системного блока 200*500 | D28: Мебель | E28: 1 | F28: шт. ( на 1 раб.место) | G28: =E28*$C$13 -> 10
A29: 4 | B29: Персональный компьютер в сборе | C29: ЦПУ: - AMD Ryzen 7 2700 @ 3.20 ГГц - количество физических ядер - 8 - количество потоков - 16 Сетевой адаптер: - технология Ethernet - 10/100/1000 mbps ОЗУ: - 16 ГБ Графический адаптер: - NVIDIA GeForce GTX 1650 - возможность подключения двух независимых мониторов ПЗУ: - SSD 256ГБ - HDD 1 ТБ | D29: Оборудование IT | E29: 1 | F29: шт. ( на 1 раб.место) | G29: =E29*$C$13 -> 10
A30: 5 | B30: Монитор | C30: Benq GW2475T | D30: Оборудование IT | E30: 2 | F30: шт. ( на 1 раб.место) | G30: =E30*$C$13 -> 20
A31: 6 | B31: Мышь для компьютера оптическая | C31: Мышь проводная Logitech B100 | D31: Оборудование IT | E31: 1 | F31: шт. ( на 1 раб.место) | G31: =E31*$C$13 -> 10
A32: 7 | B32: Клавиатура | C32: Клавиатура проводная Logitech K120 | D32: Оборудование IT | E32: 1 | F32: шт. ( на 1 раб.место) | G32: =E32*$C$13 -> 10
A33: 8 | B33: Интерфейсный кабель для подключения монитора | C33: HDMI-HDMI | D33: Оборудование IT | E33: 1 | F33: шт. ( на 1 раб.место) | G33: =E33*$C$13 -> 10
A34: 9 | B34: Интерфейсный кабель для подключения монитора | C34: DisplayPort-HDMI | D34: Оборудование IT | E34: 1 | F34: шт. ( на 1 раб.место) | G34: =E34*$C$13 -> 10
A35: 10 | B35: Планшет с ОС Android | C35: Планшет Lenovo TB-X606F Android 10, включая интерфейсный кабель для подключения к ПК | D35: Оборудование IT | E35: 1 | F35: шт. ( на 1 раб.место) | G35: =E35*$C$13 -> 10
A36: 11 | B36: Кабель питания | C36: Кабель питания CEE 7/7 - IEC 320 C13 | D36: Оборудование IT | E36: 3 | F36: шт. ( на 1 раб.место) | G36: =E36*$C$13 -> 30
A37: 12 | B37: ПО операционная система | C37: Microsoft Windows 11 | D37: ПО | E37: 1 | F37: шт. ( на 1 раб.место) | G37: =E37*$C$13 -> 10
... A58: 33 | B58: ПО среда разработки | C58: Программное обеспечение PyCharm Professional 2025.3 | D58: ПО | E58: 1 | F58: шт. ( на 1 раб.место) | G58: =E58*$C$13 -> 10
A59: 34 | B59: Текстовый редактор | C59: Sublime Text 4 Сборка 4200
A60: 35 | B60: Текстовый редактор | C60: Программное обеспечение текстовый редактор Notepad++ v8.8.9 | D60: ПО | E60: 1 | F60: шт. ( на 1 раб.место) | G60: =E60*$C$13 -> 10
...

Sheet Расходные материалы
A1: Инфраструктурный лист для оснащения конкурсной площадки
A2: ='Информация о Чемпионате'!B4 -> Региональный этап чемпионат по профессиональному мастерству "Профессионалы" в 2026 г.
A3: по компетенции
A4: ='Информация о Чемпионате'!B3 -> Программные решения для бизнеса
A5: Основная информация о конкурсной площадке:
A6: Субъект Российской Федерации: | C6: ='Информация о Чемпионате'!B5 -> Санкт-Петербург
A7: Базовая организация расположения конкурсной площадки: | D7: ='Информация о Чемпионате'!B6 -> Санкт-Петербургский колледж телекоммуникаций им. Э.Т. Кренкеля ФГБОУ ВО "Санкт-Петербургский государственный университет телекоммуникаций им. проф. М.А.Бонч-Бруевича"
A8: Адрес базовой организации: | C8: ='Информация о Чемпионате'!B7 -> г. Санкт-Петербург, наб. реки Мойки, д. 61, лит. А.
A9: Главный эксперт: | C9: ='Информация о Чемпионате'!B9 -> Кривоносова Наталья Викторовна | E9: ='Информация о Чемпионате'!B10 -> nvkrivonosowa@mail.ru | G9: ='Информация о Чемпионате'!B11 -> +7(952)385-42-25
A10: Технический администратор площадки: | C10: ='Информация о Чемпионате'!B12 -> Андреев Михаил Дмитриевич | E10: ='Информация о Чемпионате'!B13 -> andreev.mikhail.8b@gmail.com | G10: ='Информация о Чемпионате'!B14 -> +79201595535
A11: Количество экспертов (ЭН+ГЭ+ИЭ) + ТАП: | C11: ='Информация о Чемпионате'!B17 -> 13
A12: Количество конкурсантов: | C12: ='Информация о Чемпионате'!B15 -> 10
A13: Количество рабочих мест: | C13: ='Информация о Чемпионате'!B16 -> 10
A14: Даты проведения: | C14: ='Информация о Чемпионате'!B8 -> 02 февраля 2026 года - 06 января 2026 года
A15: Рабочее место Конкурсанта (расходные материалы по количеству конкурсантов)
A16: № | B16: Наименование | C16: Краткие (рамочные) технические характеристики | D16: Вид | E16: Количество | F16: Единица измерения | G16: Итоговое количество | H16: Рекомендации представителей индустрии (указывается конкретное оборудование)
A17: 1 | B17: Бумага | C17: Белая, А4 | D17: Расходные материалы | E17: 20 | F17: шт. ( на 1 конкурсанта) | G17: =E17*$C$13 -> 200
A18: 2 | B18: Ручка | C18: Ручка шариковая | D18: Расходные материалы | E18: 1 | F18: шт. ( на 1 конкурсанта) | G18: =E18*$C$13 -> 10
A19: 5 | B19: Папка-конверт на кнопке А4 | C19: Папка-конверт на кнопке А4 | D19: Расходные материалы | E19: 1 | F19: шт. ( на 1 конкурсанта) | G19: =E19*$C$13 -> 10
A20: Расходные материалы на всех конкурсантов и экспертов
A21: № | B21: Наименование | C21: Краткие (рамочные) технические характеристики | D21: Вид | E21: Количество | F21: Единица измерения | G21: Итоговое количество | H21: Рекомендации представителей индустрии (указывается конкретное оборудование)
A22: 1 | B22: Бумага | C22: Белая, А4, пачка 500 листов | D22: Расходные материалы | E22: 8 | F22: шт. | G22: 8
A23: 2 | B23: Ручка шариковая | C23: Ручка шариковая | D23: Расходные материалы | E23: 14 | F23: шт. | G23: 14
A24: 3 | B24: Степлер + скобы | C24: Степлер + скобы | D24: Расходные материалы | E24: 1 | F24: шт. | G24: 1
A25: 4 | B25: Скрепки | C25: Скрепки | D25: Расходные материалы | E25: 1 | F25: Коробка | G25: 1
A26: 5 | B26: Ножницы | C26: Ножницы | D26: Расходные материалы | E26: 1 | F26: шт. | G26: 1
A27: 6 | B27: Нож канцелярский | C27: Нож канцелярский | D27: Расходные материалы | E27: 1 | F27: шт. | G27: 1
A28: 7 | B28: Стикеры | C28: С клейкой полосой. 100 шт.. в блоке. | D28: Расходные материалы | E28: 1 | F28: Блок | G28: 1
A29: 8 | B29: Клейкая лента прозрачная | C29: 50 мм ширина | D29: Расходные материалы | E29: 1 | F29: шт. | G29: 1
A30: 9 | B30: Зажим для бумаг | C30: 32 мм, 12 шт.. в упаковке | D30: Расходные материалы | E30: 1 | F30: Упаковка | G30: 1
A31: 10 | B31: Линейка 30 см | C31: 30 см, метрическая | D31: Расходные материалы | E31: 5 | F31: шт. | G31: 5
A32: 11 | B32: Файл канцелярский | C32: А4 | D32: Расходные материалы | E32: 100 | F32: Пачка | G32: 1
A33: Охрана труда и техника безопасности
A34: № | B34: Наименование | C34: Краткие (рамочные) технические характеристики | D34: Вид | E34: Количество | F34: Единица измерения | G34: Итоговое количество | H34: Рекомендации представителей индустрии (указывается конкретное оборудование)
A35: 1 | B35: Огнетушитель | C35: ОУ-1 | D35: Охрана труда | E35: 3 | F35: шт | G35: =E35 -> 3
A36: 2 | B36: Аптечка первой помощи | C36: Для сотрудников | D36: Охрана труда | E36: 3 | F36: шт | G36: =E36 -> 3
A37: 3 | B37: Кулер с питьевой водой или бутылированная вода | C37: На усмотрение организатора | D37: Охрана труда | E37: 1 | F37: шт | G37: 1

Sheet Личный инструмент конкурсанта
A1: Инфраструктурный лист для оснащения конкурсной площадки
A2: ='Информация о Чемпионате'!B4 -> Региональный этап чемпионат по профессиональному мастерству "Профессионалы" в 2026 г.
A3: по компетенции
A4: ='Информация о Чемпионате'!B3 -> Программные решения для бизнеса
A5: Личный инструмент конкурсанта
A6: № | B6: Наименование | C6: Краткие (рамочные) технические характеристики | D6: Вид | E6: Количество | F6: Единица измерения | G6: Примечание
A7: 1 | B7: не предусмотрен
